Workbook

Sheet Cover
A1: DEMONSTRATION DOCUMENT — illustrative, prepared for the Capital Q product demo. Not a legal or financial record.
A2: Capital Q — Financial model 2026–2028
A4: Home of Private Capital · Lagos, Nigeria · pre-seed
A6: What this is: an illustrative 36-month model (Jan 2026 – Dec 2028) built for the Capital Q product demo.
A7: Jan–Sep 2026 are self-reported demonstration actuals; Oct 2026 onward is forecast. Nothing here is verified.
A8: Figures shared with the Capital Q profile (MRR, ARR, accounts, margins, team, raise) reconcile on 'Annual Summary'.
A10: Sheets: Assumptions (all inputs) · Monthly Model (formulas) · Annual Summary (roll-up and reconciliation).
A11: Colour key: blue text = hardcoded input · black = formula · green = link to another sheet · yellow fill = key assumption.
A12: Currency: USD throughout. Cash is modelled before tax; no debt.

Sheet Assumptions
A1: DEMONSTRATION DOCUMENT — illustrative, prepared for the Capital Q product demo. Not a legal or financial record.
A2: Assumptions (inputs)
A4: Input | B4: Unit | C4: 2026 | D4: 2027 | E4: 2028 | F4: Note / source
A5: Revenue
A6: New paying investor firms per month, Jan–Jun | B6: accounts | C6: 0 | D6: 3 | E6: 8 | F6: Forecast months only; 2026 H1 is actual.
A7: New paying investor firms per month, Jul–Dec | B7: accounts | C7: 2 | D7: 5 | E7: 8 | F7: Used from Oct 2026 (Jul–Sep 2026 are actual).
A8: Monthly logo churn | B8: % / month | C8: 0.015 | D8: 0.015 | E8: 0.015 | F8: Illustrative; pilot cohort too young to measure.
A9: ARPA growth (expansion) | B9: % / month | C9: 0.01 | D9: 0.01 | E9: 0.01 | F9: Seats and GateQ add-ons; NRR 112% reported Q3 2026.
A11: Cost of revenue and variable costs
A12: Cost of revenue (hosting, model inference, payment fees) | B12: % of revenue | C12: 0.22 | D12: 0.22 | E12: 0.22 | F12: Gives the 78% gross margin reported for Q3 2026.
A13: Variable pilot onboarding and support | B13: % of revenue | C13: 0.17 | D13: 0.17 | E13: 0.17 | F13: Gives the 61% contribution margin reported for Q3 2026.
A15: People (monthly cost per head)
A16: Founders | B16: USD / head / month | C16: 1200 | D16: 2500 | E16: 3000 | F16: Founders take modest pay until the SAFE closes.
A17: Engineering | B17: USD / head / month | C17: 2000 | D17: 3000 | E17: 3300 | F17: Lagos market rates, illustrative.
A18: Go-to-market and operations | B18: USD / head / month | C18: 1500 | D18: 2200 | E18: 2400 | F18: Investor network, partnerships, customer success.
A19: Employer on-costs (pension, HMO, levies) | B19: % of salary | C19: 0.1 | D19: 0.1 | E19: 0.1 | F19: Illustrative.
A21: Fixed operating costs (per month)
A22: Software and tools | B22: USD / month | C22: 600 | D22: 1500 | E22: 2500
A23: Office and co-working | B23: USD / month | C23: 400 | D23: 1200 | E23: 1800
A24: Legal, accounting and compliance | B24: USD / month | C24: 300 | D24: 1500 | E24: 1500
A25: Travel and investor-network events (West and East Africa) | B25: USD / month | C25: 500 | D25: 4000 | E25: 6000 | F25: Use of funds: grow the investor network.
A26: Marketing | B26: USD / month | C26: 300 | D26: 3000 | E26: 5000
A27: Verification and data-room partnerships | B27: USD / month | C27: 0 | D27: 2500 | E27: 3000 | F27: Use of funds: Capital Q's own verification and data-room partnerships.
A29: Funding and cash
A30: Opening cash, 1 Jan 2026 (founder funding) | B30: USD | C30: 220000
A31: Pre-seed SAFE amount | B31: USD | C31: 1500000 | F31: Matches companies.json raise target (USD 1,500,000, SAFE, pre-seed).
A32: SAFE cash received — year | B32: year | C32: 2027
A33: SAFE cash received — month | B33: month (1–12) | C33: 3 | F33: Target close 2027-03-31; modelled as received in March 2027.
A35: Actuals (self-reported demonstration data, Jan–Sep 2026)
A36: Entered directly as blue inputs on 'Monthly Model' rows 'Paying investor firms' and 'MRR' for Jan–Sep 2026.

Sheet Annual Summary
A1: DEMONSTRATION DOCUMENT — illustrative, prepared for the Capital Q product demo. Not a legal or financial record.
A2: Annual summary and reconciliation to the Capital Q profile
A4: USD unless stated | B4: FY2026 | C4: FY2027 | D4: FY2028
A5: Revenue | B5: =SUMIF('Monthly Model'!$C$5:$AL$5,2026,'Monthly Model'!$C$13:$AL$13) -> 37915.924 | C5: =SUMIF('Monthly Model'!$C$5:$AL$5,2027,'Monthly Model'!$C$13:$AL$13) -> 201031.72 | D5: =SUMIF('Monthly Model'!$C$5:$AL$5,2028,'Monthly Model'!$C$13:$AL$13) -> 617301.52
A6: Cost of revenue | B6: =SUMIF('Monthly Model'!$C$5:$AL$5,2026,'Monthly Model'!$C$17:$AL$17) -> 8341.5034 | C6: =SUMIF('Monthly Model'!$C$5:$AL$5,2027,'Monthly Model'!$C$17:$AL$17) -> 44226.978 | D6: =SUMIF('Monthly Model'!$C$5:$AL$5,2028,'Monthly Model'!$C$17:$AL$17) -> 135806.33
A7: Gross profit | B7: =SUMIF('Monthly Model'!$C$5:$AL$5,2026,'Monthly Model'!$C$18:$AL$18) -> 29574.421 | C7: =SUMIF('Monthly Model'!$C$5:$AL$5,2027,'Monthly Model'!$C$18:$AL$18) -> 156804.74 | D7: =SUMIF('Monthly Model'!$C$5:$AL$5,2028,'Monthly Model'!$C$18:$AL$18) -> 481495.18
A8: Gross margin | B8: =IF(SUMIF('Monthly Model'!$C$5:$AL$5,2026,'Monthly Model'!$C$13:$AL$13)=0,0,SUMIF('Monthly Model'!$C$5:$AL$5,2026,'Monthly Model'!$C$18:$AL$18)/SUMIF('Monthly Model'!$C$5:$AL$5,2026,'Monthly Model'!$C$13:$AL$13)) -> 0.78 | C8: =IF(SUMIF('Monthly Model'!$C$5:$AL$5,2027,'Monthly Model'!$C$13:$AL$13)=0,0,SUMIF('Monthly Model'!$C$5:$AL$5,2027,'Monthly Model'!$C$18:$AL$18)/SUMIF('Monthly Model'!$C$5:$AL$5,2027,'Monthly Model'!$C$13:$AL$13)) -> 0.78 | D8: =IF(SUMIF('Monthly Model'!$C$5:$AL$5,2028,'Monthly Model'!$C$13:$AL$13)=0,0,SUMIF('Monthly Model'!$C$5:$AL$5,2028,'Monthly Model'!$C$18:$AL$18)/SUMIF('Monthly Model'!$C$5:$AL$5,2028,'Monthly Model'!$C$13:$AL$13)) -> 0.78
A9: Contribution | B9: =SUMIF('Monthly Model'!$C$5:$AL$5,2026,'Monthly Model'!$C$21:$AL$21) -> 23128.714 | C9: =SUMIF('Monthly Model'!$C$5:$AL$5,2027,'Monthly Model'!$C$21:$AL$21) -> 122629.35 | D9: =SUMIF('Monthly Model'!$C$5:$AL$5,2028,'Monthly Model'!$C$21:$AL$21) -> 376553.92
A10: Contribution margin | B10: =IF(SUMIF('Monthly Model'!$C$5:$AL$5,2026,'Monthly Model'!$C$13:$AL$13)=0,0,SUMIF('Monthly Model'!$C$5:$AL$5,2026,'Monthly Model'!$C$21:$AL$21)/SUMIF('Monthly Model'!$C$5:$AL$5,2026,'Monthly Model'!$C$13:$AL$13)) -> 0.61 | C10: =IF(SUMIF('Monthly Model'!$C$5:$AL$5,2027,'Monthly Model'!$C$13:$AL$13)=0,0,SUMIF('Monthly Model'!$C$5:$AL$5,2027,'Monthly Model'!$C$21:$AL$21)/SUMIF('Monthly Model'!$C$5:$AL$5,2027,'Monthly Model'!$C$13:$AL$13)) -> 0.61 | D10: =IF(SUMIF('Monthly Model'!$C$5:$AL$5,2028,'Monthly Model'!$C$13:$AL$13)=0,0,SUMIF('Monthly Model'!$C$5:$AL$5,2028,'Monthly Model'!$C$21:$AL$21)/SUMIF('Monthly Model'!$C$5:$AL$5,2028,'Monthly Model'!$C$13:$AL$13)) -> 0.61
A11: Payroll incl. on-costs | B11: =SUMIF('Monthly Model'!$C$5:$AL$5,2026,'Monthly Model'!$C$31:$AL$31) -> 119130 | C11: =SUMIF('Monthly Model'!$C$5:$AL$5,2027,'Monthly Model'!$C$31:$AL$31) -> 330660 | D11: =SUMIF('Monthly Model'!$C$5:$AL$5,2028,'Monthly Model'!$C$31:$AL$31) -> 564300
A12: Total operating costs | B12: =SUMIF('Monthly Model'!$C$5:$AL$5,2026,'Monthly Model'!$C$38:$AL$38) -> 144330 | C12: =SUMIF('Monthly Model'!$C$5:$AL$5,2027,'Monthly Model'!$C$38:$AL$38) -> 495060 | D12: =SUMIF('Monthly Model'!$C$5:$AL$5,2028,'Monthly Model'!$C$38:$AL$38) -> 801900
A13: EBITDA | B13: =SUMIF('Monthly Model'!$C$5:$AL$5,2026,'Monthly Model'!$C$40:$AL$40) -> -121201.29 | C13: =SUMIF('Monthly Model'!$C$5:$AL$5,2027,'Monthly Model'!$C$40:$AL$40) -> -372430.65 | D13: =SUMIF('Monthly Model'!$C$5:$AL$5,2028,'Monthly Model'!$C$40:$AL$40) -> -425346.08
A14: Net burn | B14: =SUMIF('Monthly Model'!$C$5:$AL$5,2026,'Monthly Model'!$C$41:$AL$41) -> 121201.29 | C14: =SUMIF('Monthly Model'!$C$5:$AL$5,2027,'Monthly Model'!$C$41:$AL$41) -> 372430.65 | D14: =SUMIF('Monthly Model'!$C$5:$AL$5,2028,'Monthly Model'!$C$41:$AL$41) -> 425346.08
A15: Equity / SAFE received | B15: =SUMIF('Monthly Model'!$C$5:$AL$5,2026,'Monthly Model'!$C$45:$AL$45) -> 0 | C15: =SUMIF('Monthly Model'!$C$5:$AL$5,2027,'Monthly Model'!$C$45:$AL$45) -> 1500000 | D15: =SUMIF('Monthly Model'!$C$5:$AL$5,2028,'Monthly Model'!$C$45:$AL$45) -> 0
A16: Closing cash (December) | B16: =INDEX('Monthly Model'!$C$46:$AL$46,12) -> 98798.714 | C16: =INDEX('Monthly Model'!$C$46:$AL$46,24) -> 1226368.1 | D16: =INDEX('Monthly Model'!$C$46:$AL$46,36) -> 801021.99
A17: Exit MRR (December) | B17: =INDEX('Monthly Model'!$C$13:$AL$13,12) -> 7162.0383 | C17: =INDEX('Monthly Model'!$C$13:$AL$13,24) -> 27504.969 | D17: =INDEX('Monthly Model'!$C$13:$AL$13,36) -> 72143.698
A18: Exit ARR run-rate (December) | B18: =INDEX('Monthly Model'!$C$14:$AL$14,12) -> 85944.459 | C18: =INDEX('Monthly Model'!$C$14:$AL$14,24) -> 330059.63 | D18: =INDEX('Monthly Model'!$C$14:$AL$14,36) -> 865724.38
A19: Paying investor firms (December) | B19: =INDEX('Monthly Model'!$C$11:$AL$11,12) -> 17.378509 | C19: =INDEX('Monthly Model'!$C$11:$AL$11,24) -> 59.228476 | D19: =INDEX('Monthly Model'!$C$11:$AL$11,36) -> 137.86732
A20: Headcount (December) | B20: =INDEX('Monthly Model'!$C$28:$AL$28,12) -> 6 | C20: =INDEX('Monthly Model'!$C$28:$AL$28,24) -> 12 | D20: =INDEX('Monthly Model'!$C$28:$AL$28,36) -> 16
A21: Runway at December (months) | B21: =INDEX('Monthly Model'!$C$47:$AL$47,12) -> 11.551223 | C21: =INDEX('Monthly Model'!$C$47:$AL$47,24) -> 36.898301 | D21: =INDEX('Monthly Model'!$C$47:$AL$47,36) -> 27.055211
A24: Reconciliation to the Capital Q profile (companies.json, as of 2026-09-30)
A25: Profile figure | B25: Profile value | C25: Model value | E25: Check | F25: Model source
A26: Monthly recurring revenue, Sep 2026 (USD) | B26: 4800 | C26: ='Monthly Model'!K13 -> 4800 | E26: =IF(ABS(C26-B26)<0.0005*MAX(1,ABS(B26)),"OK","CHECK") -> OK | F26: Monthly Model, Sep 26
A27: ARR run-rate, end Sep 2026 (USD) | B27: 57600 | C27: ='Monthly Model'!K14 -> 57600 | E27: =IF(ABS(C27-B27)<0.0005*MAX(1,ABS(B27)),"OK","CHECK") -> OK | F27: MRR × 12
A28: Paying investor firms, Sep 2026 | B28: 12 | C28: ='Monthly Model'!K11 -> 12 | E28: =IF(ABS(C28-B28)<0.0005*MAX(1,ABS(B28)),"OK","CHECK") -> OK | F28: Monthly Model, Sep 26
A29: MRR growth Jun → Sep 2026 | B29: 0.6 | C29: ='Monthly Model'!K13/'Monthly Model'!H13-1 -> 0.6 | E29: =IF(ABS(C29-B29)<0.0005*MAX(1,ABS(B29)),"OK","CHECK") -> OK | F29: USD 3,000 → USD 4,800
A30: Gross margin, Q3 2026 | B30: 0.78 | C30: =SUM('Monthly Model'!I18:K18)/SUM('Monthly Model'!I13:K13) -> 0.78 | E30: =IF(ABS(C30-B30)<0.0005*MAX(1,ABS(B30)),"OK","CHECK") -> OK | F30: Jul–Sep 2026
A31: Contribution margin, Q3 2026 | B31: 0.61 | C31: =SUM('Monthly Model'!I21:K21)/SUM('Monthly Model'!I13:K13) -> 0.61 | E31: =IF(ABS(C31-B31)<0.0005*MAX(1,ABS(B31)),"OK","CHECK") -> OK | F31: Jul–Sep 2026
A32: Team size, Sep 2026 | B32: 6 | C32: ='Monthly Model'!K28 -> 6 | E32: =IF(ABS(C32-B32)<0.0005*MAX(1,ABS(B32)),"OK","CHECK") -> OK | F32: Headcount, Sep 26
A33: Pre-seed SAFE raise (USD) | B33: 1500000 | C33: =Assumptions!C31 -> 1500000 | E33: =IF(ABS(C33-B33)<0.0005*MAX(1,ABS(B33)),"OK","CHECK") -> OK | F33: Assumptions
A35: Reported but not modelled: net revenue retention 112% (Q3 2026); 1,240 active founders and investors (Sep 2026);
A36: estimated market USD 1.2 billion annual spend on deal sourcing and diligence tools (ESTIMATE). All self-reported, unverified.

Sheet Monthly Model
A1: DEMONSTRATION DOCUMENT — illustrative, prepared for the Capital Q product demo. Not a legal or financial record.
A2: Monthly model, USD (Jan 2026 – Dec 2028)
A4: Line | B4: Unit | C4: Jan 26 | D4: Feb 26 | E4: Mar 26 | F4: Apr 26 | G4: May 26 | H4: Jun 26 | I4: Jul 26 | J4: Aug 26 | K4: Sep 26 | L4: Oct 26 | M4: Nov 26 | N4: Dec 26 | O4: Jan 27 | P4: Feb 27 | Q4: Mar 27 | R4: Apr 27 | S4: May 27 | T4: Jun 27 | U4: Jul 27 | V4: Aug 27 | W4: Sep 27 | X4: Oct 27 | Y4: Nov 27 | Z4: Dec 27 | AA4: Jan 28 | AB4: Feb 28 | AC4: Mar 28 | AD4: Apr 28 | AE4: May 28 | AF4: Jun 28 | AG4: Jul 28 | AH4: Aug 28 | AI4: Sep 28 | AJ4: Oct 28 | AK4: Nov 28 | AL4: Dec 28
A5: Year | C5: 2026 | D5: 2026 | E5: 2026 | F5: 2026 | G5: 2026 | H5: 2026 | I5: 2026 | J5: 2026 | K5: 2026 | L5: 2026 | M5: 2026 | N5: 2026 | O5: 2027 | P5: 2027 | Q5: 2027 | R5: 2027 | S5: 2027 | T5: 2027 | U5: 2027 | V5: 2027 | W5: 2027 | X5: 2027 | Y5: 2027 | Z5: 2027 | AA5: 2028 | AB5: 2028 | AC5: 2028 | AD5: 2028 | AE5: 2028 | AF5: 2028 | AG5: 2028 | AH5: 2028 | AI5: 2028 | AJ5: 2028 | AK5: 2028 | AL5: 2028
A6: Month | C6: 1 | D6: 2 | E6: 3 | F6: 4 | G6: 5 | H6: 6 | I6: 7 | J6: 8 | K6: 9 | L6: 10 | M6: 11 | N6: 12 | O6: 1 | P6: 2 | Q6: 3 | R6: 4 | S6: 5 | T6: 6 | U6: 7 | V6: 8 | W6: 9 | X6: 10 | Y6: 11 | Z6: 12 | AA6: 1 | AB6: 2 | AC6: 3 | AD6: 4 | AE6: 5 | AF6: 6 | AG6: 7 | AH6: 8 | AI6: 9 | AJ6: 10 | AK6: 11 | AL6: 12
A7: Actual / forecast | C7: Actual | D7: Actual | E7: Actual | F7: Actual | G7: Actual | H7: Actual | I7: Actual | J7: Actual | K7: Actual | L7: Forecast | M7: Forecast | N7: Forecast | O7: Forecast | P7: Forecast | Q7: Forecast | R7: Forecast | S7: Forecast | T7: Forecast | U7: Forecast | V7: Forecast | W7: Forecast | X7: Forecast | Y7: Forecast | Z7: Forecast | AA7: Forecast | AB7: Forecast | AC7: Forecast | AD7: Forecast | AE7: Forecast | AF7: Forecast | AG7: Forecast | AH7: Forecast | AI7: Forecast | AJ7: Forecast | AK7: Forecast | AL7: Forecast
A9: REVENUE
A10: New paying investor firms | B10: accounts | L10: =IF(L$6<=6,INDEX(Assumptions!$C$6:$E$6,(L$5-2025)),INDEX(Assumptions!$C$7:$E$7,(L$5-2025))) -> 2 | M10: =IF(M$6<=6,INDEX(Assumptions!$C$6:$E$6,(M$5-2025)),INDEX(Assumptions!$C$7:$E$7,(M$5-2025))) -> 2 | N10: =IF(N$6<=6,INDEX(Assumptions!$C$6:$E$6,(N$5-2025)),INDEX(Assumptions!$C$7:$E$7,(N$5-2025))) -> 2 | O10: =IF(O$6<=6,INDEX(Assumptions!$C$6:$E$6,(O$5-2025)),INDEX(Assumptions!$C$7:$E$7,(O$5-2025))) -> 3 | P10: =IF(P$6<=6,INDEX(Assumptions!$C$6:$E$6,(P$5-2025)),INDEX(Assumptions!$C$7:$E$7,(P$5-2025))) -> 3 | Q10: =IF(Q$6<=6,INDEX(Assumptions!$C$6:$E$6,(Q$5-2025)),INDEX(Assumptions!$C$7:$E$7,(Q$5-2025))) -> 3 | R10: =IF(R$6<=6,INDEX(Assumptions!$C$6:$E$6,(R$5-2025)),INDEX(Assumptions!$C$7:$E$7,(R$5-2025))) -> 3 | S10: =IF(S$6<=6,INDEX(Assumptions!$C$6:$E$6,(S$5-2025)),INDEX(Assumptions!$C$7:$E$7,(S$5-2025))) -> 3 | ... AL10: =IF(AL$6<=6,INDEX(Assumptions!$C$6:$E$6,(AL$5-2025)),INDEX(Assumptions!$C$7:$E$7,(AL$5-2025))) -> 8
A11: Paying investor firms (end of month) | B11: accounts | C11: 0 | D11: 0 | E11: 0 | F11: 3 | G11: 5 | H11: 8 | I11: 9 | J11: 10 | K11: 12 | L11: =K11*(1-INDEX(Assumptions!$C$8:$E$8,(L$5-2025)))+L10 -> 13.82 | M11: =L11*(1-INDEX(Assumptions!$C$8:$E$8,(M$5-2025)))+M10 -> 15.6127 | N11: =M11*(1-INDEX(Assumptions!$C$8:$E$8,(N$5-2025)))+N10 -> 17.378509 | O11: =N11*(1-INDEX(Assumptions!$C$8:$E$8,(O$5-2025)))+O10 -> 20.117832 | P11: =O11*(1-INDEX(Assumptions!$C$8:$E$8,(P$5-2025)))+P10 -> 22.816064 | Q11: =P11*(1-INDEX(Assumptions!$C$8:$E$8,(Q$5-2025)))+Q10 -> 25.473823 | R11: =Q11*(1-INDEX(Assumptions!$C$8:$E$8,(R$5-2025)))+R10 -> 28.091716 | S11: =R11*(1-INDEX(Assumptions!$C$8:$E$8,(S$5-2025)))+S10 -> 30.67034 | ... AL11: =AK11*(1-INDEX(Assumptions!$C$8:$E$8,(AL$5-2025)))+AL10 -> 137.86732
A12: ARPA (average revenue per account) | B12: USD | C12: =IF(C11=0,0,C13/C11) -> 0 | D12: =IF(D11=0,0,D13/D11) -> 0 | E12: =IF(E11=0,0,E13/E11) -> 0 | F12: =IF(F11=0,0,F13/F11) -> 400 | G12: =IF(G11=0,0,G13/G11) -> 400 | H12: =IF(H11=0,0,H13/H11) -> 375 | I12: =IF(I11=0,0,I13/I11) -> 400 | J12: =IF(J11=0,0,J13/J11) -> 420 | K12: =IF(K11=0,0,K13/K11) -> 400 | L12: =K12*(1+INDEX(Assumptions!$C$9:$E$9,(L$5-2025))) -> 404 | M12: =L12*(1+INDEX(Assumptions!$C$9:$E$9,(M$5-2025))) -> 408.04 | N12: =M12*(1+INDEX(Assumptions!$C$9:$E$9,(N$5-2025))) -> 412.1204 | O12: =N12*(1+INDEX(Assumptions!$C$9:$E$9,(O$5-2025))) -> 416.2416 | P12: =O12*(1+INDEX(Assumptions!$C$9:$E$9,(P$5-2025))) -> 420.40402 | Q12: =P12*(1+INDEX(Assumptions!$C$9:$E$9,(Q$5-2025))) -> 424.60806 | R12: =Q12*(1+INDEX(Assumptions!$C$9:$E$9,(R$5-2025))) -> 428.85414 | S12: =R12*(1+INDEX(Assumptions!$C$9:$E$9,(S$5-2025))) -> 433.14268 | ... AL12: =AK12*(1+INDEX(Assumptions!$C$9:$E$9,(AL$5-2025))) -> 523.28355
A13: MRR (monthly recurring revenue) | B13: USD | C13: 0 | D13: 0 | E13: 0 | F13: 1200 | G13: 2000 | H13: 3000 | I13: 3600 | J13: 4200 | K13: 4800 | L13: =L11*L12 -> 5583.28 | M13: =M11*M12 -> 6370.6061 | N13: =N11*N12 -> 7162.0383 | O13: =O11*O12 -> 8373.8786 | P13: =P11*P12 -> 9591.9652 | Q13: =Q11*Q12 -> 10816.391 | R13: =R11*R12 -> 12047.249 | S13: =S11*S12 -> 13284.633 | ... AL13: =AL11*AL12 -> 72143.698
A14: ARR run-rate (MRR × 12) | B14: USD | C14: =C13*12 -> 0 | D14: =D13*12 -> 0 | E14: =E13*12 -> 0 | F14: =F13*12 -> 14400 | G14: =G13*12 -> 24000 | H14: =H13*12 -> 36000 | I14: =I13*12 -> 43200 | J14: =J13*12 -> 50400 | ... AL14: =AL13*12 -> 865724.38
A16: MARGINS
A17: Cost of revenue | B17: USD | C17: =C13*INDEX(Assumptions!$C$12:$E$12,(C$5-2025)) -> 0 | D17: =D13*INDEX(Assumptions!$C$12:$E$12,(D$5-2025)) -> 0 | E17: =E13*INDEX(Assumptions!$C$12:$E$12,(E$5-2025)) -> 0 | F17: =F13*INDEX(Assumptions!$C$12:$E$12,(F$5-2025)) -> 264 | G17: =G13*INDEX(Assumptions!$C$12:$E$12,(G$5-2025)) -> 440 | H17: =H13*INDEX(Assumptions!$C$12:$E$12,(H$5-2025)) -> 660 | I17: =I13*INDEX(Assumptions!$C$12:$E$12,(I$5-2025)) -> 792 | J17: =J13*INDEX(Assumptions!$C$12:$E$12,(J$5-2025)) -> 924 | ... AL17: =AL13*INDEX(Assumptions!$C$12:$E$12,(AL$5-2025)) -> 15871.614
A18: Gross profit | B18: USD | C18: =C13-C17 -> 0 | D18: =D13-D17 -> 0 | E18: =E13-E17 -> 0 | F18: =F13-F17 -> 936 | G18: =G13-G17 -> 1560 | H18: =H13-H17 -> 2340 | I18: =I13-I17 -> 2808 | J18: =J13-J17 -> 3276 | ... AL18: =AL13-AL17 -> 56272.085
A19: Gross margin | B19: % | C19: =IF(C13=0,0,C18/C13) -> 0 | D19: =IF(D13=0,0,D18/D13) -> 0 | E19: =IF(E13=0,0,E18/E13) -> 0 | F19: =IF(F13=0,0,F18/F13) -> 0.78 | G19: =IF(G13=0,0,G18/G13) -> 0.78 | H19: =IF(H13=0,0,H18/H13) -> 0.78 | I19: =IF(I13=0,0,I18/I13) -> 0.78 | J19: =IF(J13=0,0,J18/J13) -> 0.78 | ... AL19: =IF(AL13=0,0,AL18/AL13) -> 0.78
A20: Variable onboarding and support | B20: USD | C20: =C13*INDEX(Assumptions!$C$13:$E$13,(C$5-2025)) -> 0 | D20: =D13*INDEX(Assumptions!$C$13:$E$13,(D$5-2025)) -> 0 | E20: =E13*INDEX(Assumptions!$C$13:$E$13,(E$5-2025)) -> 0 | F20: =F13*INDEX(Assumptions!$C$13:$E$13,(F$5-2025)) -> 204 | G20: =G13*INDEX(Assumptions!$C$13:$E$13,(G$5-2025)) -> 340 | H20: =H13*INDEX(Assumptions!$C$13:$E$13,(H$5-2025)) -> 510 | I20: =I13*INDEX(Assumptions!$C$13:$E$13,(I$5-2025)) -> 612 | J20: =J13*INDEX(Assumptions!$C$13:$E$13,(J$5-2025)) -> 714 | ... AL20: =AL13*INDEX(Assumptions!$C$13:$E$13,(AL$5-2025)) -> 12264.429
A21: Contribution | B21: USD | C21: =C18-C20 -> 0 | D21: =D18-D20 -> 0 | E21: =E18-E20 -> 0 | F21: =F18-F20 -> 732 | G21: =G18-G20 -> 1220 | H21: =H18-H20 -> 1830 | I21: =I18-I20 -> 2196 | J21: =J18-J20 -> 2562 | ... AL21: =AL18-AL20 -> 44007.656
A22: Contribution margin | B22: % | C22: =IF(C13=0,0,C21/C13) -> 0 | D22: =IF(D13=0,0,D21/D13) -> 0 | E22: =IF(E13=0,0,E21/E13) -> 0 | F22: =IF(F13=0,0,F21/F13) -> 0.61 | G22: =IF(G13=0,0,G21/G13) -> 0.61 | H22: =IF(H13=0,0,H21/H13) -> 0.61 | I22: =IF(I13=0,0,I21/I13) -> 0.61 | J22: =IF(J13=0,0,J21/J13) -> 0.61 | ... AL22: =IF(AL13=0,0,AL21/AL13) -> 0.61
A24: HEADCOUNT (end of month)
A25: Founders | B25: people | C25: 2 | D25: 2 | E25: 2 | F25: 2 | G25: 2 | H25: 2 | I25: 2 | J25: 2 | K25: 2 | L25: 2 | M25: 2 | N25: 2 | O25: 2 | P25: 2 | Q25: 2 | R25: 2 | S25: 2 | T25: 2 | U25: 2 | V25: 2 | W25: 2 | X25: 2 | Y25: 2 | Z25: 2 | AA25: 2 | AB25: 2 | AC25: 2 | AD25: 2 | AE25: 2 | AF25: 2 | AG25: 2 | AH25: 2 | AI25: 2 | AJ25: 2 | AK25: 2 | AL25: 2
A26: Engineering | B26: people | C26: 2 | D26: 2 | E26: 2 | F26: 2 | G26: 2 | H26: 2 | I26: 2 | J26: 2 | K26: 2 | L26: 2 | M26: 2 | N26: 2 | O26: 2 | P26: 2 | Q26: 2 | R26: 4 | S26: 4 | T26: 6 | U26: 6 | V26: 6 | W26: 6 | X26: 6 | Y26: 6 | Z26: 6 | AA26: 7 | AB26: 7 | AC26: 7 | AD26: 7 | AE26: 7 | AF26: 7 | AG26: 8 | AH26: 8 | AI26: 8 | AJ26: 8 | AK26: 8 | AL26: 8
A27: Go-to-market and operations | B27: people | C27: 1 | D27: 1 | E27: 1 | F27: 2 | G27: 2 | H27: 2 | I27: 2 | J27: 2 | K27: 2 | L27: 2 | M27: 2 | N27: 2 | O27: 2 | P27: 2 | Q27: 2 | R27: 2 | S27: 2 | T27: 2 | U27: 3 | V27: 3 | W27: 3 | X27: 4 | Y27: 4 | Z27: 4 | AA27: 4 | AB27: 4 | AC27: 4 | AD27: 5 | AE27: 5 | AF27: 5 | AG27: 5 | AH27: 5 | AI27: 5 | AJ27: 6 | AK27: 6 | AL27: 6
A28: Total headcount | B28: people | C28: =SUM(C25:C27) -> 5 | D28: =SUM(D25:D27) -> 5 | E28: =SUM(E25:E27) -> 5 | F28: =SUM(F25:F27) -> 6 | G28: =SUM(G25:G27) -> 6 | H28: =SUM(H25:H27) -> 6 | I28: =SUM(I25:I27) -> 6 | J28: =SUM(J25:J27) -> 6 | ... AL28: =SUM(AL25:AL27) -> 16
A30: OPERATING COSTS
A31: Payroll incl. on-costs | B31: USD | C31: =(C25*INDEX(Assumptions!$C$16:$E$16,(C$5-2025))+C26*INDEX(Assumptions!$C$17:$E$17,(C$5-2025))+C27*INDEX(Assumptions!$C$18:$E$18,(C$5-2025)))*(1+INDEX(Assumptions!$C$19:$E$19,(C$5-2025))) -> 8690 | D31: =(D25*INDEX(Assumptions!$C$16:$E$16,(D$5-2025))+D26*INDEX(Assumptions!$C$17:$E$17,(D$5-2025))+D27*INDEX(Assumptions!$C$18:$E$18,(D$5-2025)))*(1+INDEX(Assumptions!$C$19:$E$19,(D$5-2025))) -> 8690 | E31: =(E25*INDEX(Assumptions!$C$16:$E$16,(E$5-2025))+E26*INDEX(Assumptions!$C$17:$E$17,(E$5-2025))+E27*INDEX(Assumptions!$C$18:$E$18,(E$5-2025)))*(1+INDEX(Assumptions!$C$19:$E$19,(E$5-2025))) -> 8690 | F31: =(F25*INDEX(Assumptions!$C$16:$E$16,(F$5-2025))+F26*INDEX(Assumptions!$C$17:$E$17,(F$5-2025))+F27*INDEX(Assumptions!$C$18:$E$18,(F$5-2025)))*(1+INDEX(Assumptions!$C$19:$E$19,(F$5-2025))) -> 10340 | G31: =(G25*INDEX(Assumptions!$C$16:$E$16,(G$5-2025))+G26*INDEX(Assumptions!$C$17:$E$17,(G$5-2025))+G27*INDEX(Assumptions!$C$18:$E$18,(G$5-2025)))*(1+INDEX(Assumptions!$C$19:$E$19,(G$5-2025))) -> 10340 | H31: =(H25*INDEX(Assumptions!$C$16:$E$16,(H$5-2025))+H26*INDEX(Assumptions!$C$17:$E$17,(H$5-2025))+H27*INDEX(Assumptions!$C$18:$E$18,(H$5-2025)))*(1+INDEX(Assumptions!$C$19:$E$19,(H$5-2025))) -> 10340 | I31: =(I25*INDEX(Assumptions!$C$16:$E$16,(I$5-2025))+I26*INDEX(Assumptions!$C$17:$E$17,(I$5-2025))+I27*INDEX(Assumptions!$C$18:$E$18,(I$5-2025)))*(1+INDEX(Assumptions!$C$19:$E$19,(I$5-2025))) -> 10340 | J31: =(J25*INDEX(Assumptions!$C$16:$E$16,(J$5-2025))+J26*INDEX(Assumptions!$C$17:$E$17,(J$5-2025))+J27*INDEX(Assumptions!$C$18:$E$18,(J$5-2025)))*(1+INDEX(Assumptions!$C$19:$E$19,(J$5-2025))) -> 10340 | ... AL31: =(AL25*INDEX(Assumptions!$C$16:$E$16,(AL$5-2025))+AL26*INDEX(Assumptions!$C$17:$E$17,(AL$5-2025))+AL27*INDEX(Assumptions!$C$18:$E$18,(AL$5-2025)))*(1+INDEX(Assumptions!$C$19:$E$19,(AL$5-2025))) -> 51480
A32: Software and tools | B32: USD | C32: =INDEX(Assumptions!$C$22:$E$22,(C$5-2025)) -> 600 | D32: =INDEX(Assumptions!$C$22:$E$22,(D$5-2025)) -> 600 | E32: =INDEX(Assumptions!$C$22:$E$22,(E$5-2025)) -> 600 | F32: =INDEX(Assumptions!$C$22:$E$22,(F$5-2025)) -> 600 | G32: =INDEX(Assumptions!$C$22:$E$22,(G$5-2025)) -> 600 | H32: =INDEX(Assumptions!$C$22:$E$22,(H$5-2025)) -> 600 | I32: =INDEX(Assumptions!$C$22:$E$22,(I$5-2025)) -> 600 | J32: =INDEX(Assumptions!$C$22:$E$22,(J$5-2025)) -> 600 | ... AL32: =INDEX(Assumptions!$C$22:$E$22,(AL$5-2025)) -> 2500
A33: Office and co-working | B33: USD | C33: =INDEX(Assumptions!$C$23:$E$23,(C$5-2025)) -> 400 | D33: =INDEX(Assumptions!$C$23:$E$23,(D$5-2025)) -> 400 | E33: =INDEX(Assumptions!$C$23:$E$23,(E$5-2025)) -> 400 | F33: =INDEX(Assumptions!$C$23:$E$23,(F$5-2025)) -> 400 | G33: =INDEX(Assumptions!$C$23:$E$23,(G$5-2025)) -> 400 | H33: =INDEX(Assumptions!$C$23:$E$23,(H$5-2025)) -> 400 | I33: =INDEX(Assumptions!$C$23:$E$23,(I$5-2025)) -> 400 | J33: =INDEX(Assumptions!$C$23:$E$23,(J$5-2025)) -> 400 | ... AL33: =INDEX(Assumptions!$C$23:$E$23,(AL$5-2025)) -> 1800
A34: Legal, accounting and compliance | B34: USD | C34: =INDEX(Assumptions!$C$24:$E$24,(C$5-2025)) -> 300 | D34: =INDEX(Assumptions!$C$24:$E$24,(D$5-2025)) -> 300 | E34: =INDEX(Assumptions!$C$24:$E$24,(E$5-2025)) -> 300 | F34: =INDEX(Assumptions!$C$24:$E$24,(F$5-2025)) -> 300 | G34: =INDEX(Assumptions!$C$24:$E$24,(G$5-2025)) -> 300 | H34: =INDEX(Assumptions!$C$24:$E$24,(H$5-2025)) -> 300 | I34: =INDEX(Assumptions!$C$24:$E$24,(I$5-2025)) -> 300 | J34: =INDEX(Assumptions!$C$24:$E$24,(J$5-2025)) -> 300 | ... AL34: =INDEX(Assumptions!$C$24:$E$24,(AL$5-2025)) -> 1500
A35: Travel and investor-network events | B35: USD | C35: =INDEX(Assumptions!$C$25:$E$25,(C$5-2025)) -> 500 | D35: =INDEX(Assumptions!$C$25:$E$25,(D$5-2025)) -> 500 | E35: =INDEX(Assumptions!$C$25:$E$25,(E$5-2025)) -> 500 | F35: =INDEX(Assumptions!$C$25:$E$25,(F$5-2025)) -> 500 | G35: =INDEX(Assumptions!$C$25:$E$25,(G$5-2025)) -> 500 | H35: =INDEX(Assumptions!$C$25:$E$25,(H$5-2025)) -> 500 | I35: =INDEX(Assumptions!$C$25:$E$25,(I$5-2025)) -> 500 | J35: =INDEX(Assumptions!$C$25:$E$25,(J$5-2025)) -> 500 | ... AL35: =INDEX(Assumptions!$C$25:$E$25,(AL$5-2025)) -> 6000
A36: Marketing | B36: USD | C36: =INDEX(Assumptions!$C$26:$E$26,(C$5-2025)) -> 300 | D36: =INDEX(Assumptions!$C$26:$E$26,(D$5-2025)) -> 300 | E36: =INDEX(Assumptions!$C$26:$E$26,(E$5-2025)) -> 300 | F36: =INDEX(Assumptions!$C$26:$E$26,(F$5-2025)) -> 300 | G36: =INDEX(Assumptions!$C$26:$E$26,(G$5-2025)) -> 300 | H36: =INDEX(Assumptions!$C$26:$E$26,(H$5-2025)) -> 300 | I36: =INDEX(Assumptions!$C$26:$E$26,(I$5-2025)) -> 300 | J36: =INDEX(Assumptions!$C$26:$E$26,(J$5-2025)) -> 300 | ... AL36: =INDEX(Assumptions!$C$26:$E$26,(AL$5-2025)) -> 5000
A37: Verification and data-room partnerships | B37: USD | C37: =INDEX(Assumptions!$C$27:$E$27,(C$5-2025)) -> 0 | D37: =INDEX(Assumptions!$C$27:$E$27,(D$5-2025)) -> 0 | E37: =INDEX(Assumptions!$C$27:$E$27,(E$5-2025)) -> 0 | F37: =INDEX(Assumptions!$C$27:$E$27,(F$5-2025)) -> 0 | G37: =INDEX(Assumptions!$C$27:$E$27,(G$5-2025)) -> 0 | H37: =INDEX(Assumptions!$C$27:$E$27,(H$5-2025)) -> 0 | I37: =INDEX(Assumptions!$C$27:$E$27,(I$5-2025)) -> 0 | J37: =INDEX(Assumptions!$C$27:$E$27,(J$5-2025)) -> 0 | ... AL37: =INDEX(Assumptions!$C$27:$E$27,(AL$5-2025)) -> 3000
A38: Total operating costs | B38: USD | C38: =SUM(C31:C37) -> 10790 | D38: =SUM(D31:D37) -> 10790 | E38: =SUM(E31:E37) -> 10790 | F38: =SUM(F31:F37) -> 12440 | G38: =SUM(G31:G37) -> 12440 | H38: =SUM(H31:H37) -> 12440 | I38: =SUM(I31:I37) -> 12440 | J38: =SUM(J31:J37) -> 12440 | ... AL38: =SUM(AL31:AL37) -> 71280
A39: Total costs (cost of revenue + variable + operating) | B39: USD | C39: =C17+C20+C38 -> 10790 | D39: =D17+D20+D38 -> 10790 | E39: =E17+E20+E38 -> 10790 | F39: =F17+F20+F38 -> 12908 | G39: =G17+G20+G38 -> 13220 | H39: =H17+H20+H38 -> 13610 | I39: =I17+I20+I38 -> 13844 | J39: =J17+J20+J38 -> 14078 | ... AL39: =AL17+AL20+AL38 -> 99416.042
A40: EBITDA | B40: USD | C40: =C13-C39 -> -10790 | D40: =D13-D39 -> -10790 | E40: =E13-E39 -> -10790 | F40: =F13-F39 -> -11708 | G40: =G13-G39 -> -11220 | H40: =H13-H39 -> -10610 | I40: =I13-I39 -> -10244 | J40: =J13-J39 -> -9878 | ... AL40: =AL13-AL39 -> -27272.344
A41: Net burn (positive = cash consumed) | B41: USD | C41: =-C40 -> 10790 | D41: =-D40 -> 10790 | E41: =-E40 -> 10790 | F41: =-F40 -> 11708 | G41: =-G40 -> 11220 | H41: =-H40 -> 10610 | I41: =-I40 -> 10244 | J41: =-J40 -> 9878 | ... AL41: =-AL40 -> 27272.344
A43: CASH
A44: Opening cash | B44: USD | C44: =Assumptions!$C$30 -> 220000 | D44: =C46 -> 209210 | E44: =D46 -> 198420 | F44: =E46 -> 187630 | G44: =F46 -> 175922 | H44: =G46 -> 164702 | I44: =H46 -> 154092 | J44: =I46 -> 143848 | K44: =J46 -> 133970 | ... AL44: =AK46 -> 828294.33
A45: Equity / SAFE received | B45: USD | C45: =IF(AND(C$5=Assumptions!$C$32,C$6=Assumptions!$C$33),Assumptions!$C$31,0) -> 0 | D45: =IF(AND(D$5=Assumptions!$C$32,D$6=Assumptions!$C$33),Assumptions!$C$31,0) -> 0 | E45: =IF(AND(E$5=Assumptions!$C$32,E$6=Assumptions!$C$33),Assumptions!$C$31,0) -> 0 | F45: =IF(AND(F$5=Assumptions!$C$32,F$6=Assumptions!$C$33),Assumptions!$C$31,0) -> 0 | G45: =IF(AND(G$5=Assumptions!$C$32,G$6=Assumptions!$C$33),Assumptions!$C$31,0) -> 0 | H45: =IF(AND(H$5=Assumptions!$C$32,H$6=Assumptions!$C$33),Assumptions!$C$31,0) -> 0 | I45: =IF(AND(I$5=Assumptions!$C$32,I$6=Assumptions!$C$33),Assumptions!$C$31,0) -> 0 | J45: =IF(AND(J$5=Assumptions!$C$32,J$6=Assumptions!$C$33),Assumptions!$C$31,0) -> 0 | ... AL45: =IF(AND(AL$5=Assumptions!$C$32,AL$6=Assumptions!$C$33),Assumptions!$C$31,0) -> 0
A46: Closing cash | B46: USD | C46: =C44+C45-C41 -> 209210 | D46: =D44+D45-D41 -> 198420 | E46: =E44+E45-E41 -> 187630 | F46: =F44+F45-F41 -> 175922 | G46: =G44+G45-G41 -> 164702 | H46: =H44+H45-H41 -> 154092 | I46: =I44+I45-I41 -> 143848 | J46: =J44+J45-J41 -> 133970 | ... AL46: =AL44+AL45-AL41 -> 801021.99
...
